Workbook
Name Opponents: Attendance!$D$46:$D$56
Name PlayerList: Attendance!$D$5:$D$24

Sheet Dashboard
B2: LUCAN UTD YOUTHS — GIRLS YOUTH | 2026/2027 LEAGUE SEASON
B3: Everything on this tab updates automatically from the Attendance tab. Only the player dropdown in the Individual Progress section is an input.
B5: {="Girls Youth Squad | GW "&MAX(1,SUMPRODUCT((Attendance!$CP$4:$FY$4="Att")*(Attendance!$CP$2:$FY$2<>"")))&" of 22 | "&SUMPRODUCT((Attendance!$E$4:$CN$4="Att")*(Attendance!$E$3:$CN$3<>""))&" sessions held | "&SUMPRODUCT((Attendance!$CP$4:$FY$4="Att")*(Attendance!$CP$28:$FY$28<>""))&" matches played | "&COUNTA(Attendance!$D$5:$D$24)&" players tracked"} -> Girls Youth Squad | GW 1 of 22 | 0 sessions held | 0 matches played | 17 players tracked
B7: Season Score | D7: Avg Training Attendance | F7: Avg Work Rate | H7: Avg Matchday Attendance | J7: Avg Match Rating | L7: Record (W-D-L) | N7: Full Attenders
B8: =IFERROR(AVERAGE(Workings!$H$6:$H$25),0) -> 0 | D8: =IFERROR(AVERAGE(Workings!$D$6:$D$25),0) -> 0 | F8: =IFERROR(AVERAGE(Workings!$E$6:$E$25),0) -> 0 | H8: =IFERROR(AVERAGE(Workings!$F$6:$F$25),0) -> 0 | J8: =IFERROR(AVERAGE(Workings!$G$6:$G$25),0) -> 0 | L8: =COUNTIF(Attendance!$CP$28:$FY$28,"W")&" - "&COUNTIF(Attendance!$CP$28:$FY$28,"D")&" - "&COUNTIF(Attendance!$CP$28:$FY$28,"L") -> 0 - 0 - 0 | N8: =COUNTIF(Workings!$D$6:$D$25,1) -> 0
AF33: PLAYER SCORECARD — training work-rate trend (44 sessions), matchday trend (22 fixtures) and season metrics
AF34: Player | AG34: Training work-rate trend (▁▃▅▆█ = 1–5, · = missed) | AH34: Matchday trend (rating bands, · = no minutes) | AI34: 1 | AJ34: 2 | AK34: 3 | AL34: 4 | AM34: 5 | AN34: 6 | AO34: 7 | AP34: 8 | AQ34: 9 | AR34: 10 | AS34: 11 | AT34: 12 | AU34: 13 | AV34: 14 | AW34: 15 | AX34: 16 | AY34: 17 | AZ34: 18 | BA34: 19 | BB34: 20 | BC34: 21 | BD34: 22 | BE34: Att % | BF34: Avg WR | BG34: Avg Rating | BH34: Season Score %
AF35: =IF(Attendance!$D5="","",Attendance!$D5) -> Aoife Kennan | AG35: {=IF($AF35="","",_xlfn.TEXTJOIN("",TRUE,IF(Attendance!$E$4:$CN$4="WR",IFERROR(CHOOSE(Attendance!$E5:$CN5,"▁","▃","▅","▆","█"),"·"),"")))} -> ············································ | AH35: {=IF($AF35="","",_xlfn.TEXTJOIN("",TRUE,IF(Attendance!$CP$4:$FY$4="Rating",IFERROR(CHOOSE(ROUNDUP(Attendance!$CP5:$FY5/2,0),"▁","▃","▅","▆","█"),"·"),"")))} -> ······················ | AI35: =IF($AF35="","",IFERROR(AVERAGE(OFFSET(Attendance!$A$1,4,5+(1-1)*4),OFFSET(Attendance!$A$1,4,7+(1-1)*4)),"")) | AJ35: =IF($AF35="","",IFERROR(AVERAGE(OFFSET(Attendance!$A$1,4,5+(2-1)*4),OFFSET(Attendance!$A$1,4,7+(2-1)*4)),"")) | AK35: =IF($AF35="","",IFERROR(AVERAGE(OFFSET(Attendance!$A$1,4,5+(3-1)*4),OFFSET(Attendance!$A$1,4,7+(3-1)*4)),"")) | AL35: =IF($AF35="","",IFERROR(AVERAGE(OFFSET(Attendance!$A$1,4,5+(4-1)*4),OFFSET(Attendance!$A$1,4,7+(4-1)*4)),"")) | AM35: =IF($AF35="","",IFERROR(AVERAGE(OFFSET(Attendance!$A$1,4,5+(5-1)*4),OFFSET(Attendance!$A$1,4,7+(5-1)*4)),"")) | AN35: =IF($AF35="","",IFERROR(AVERAGE(OFFSET(Attendance!$A$1,4,5+(6-1)*4),OFFSET(Attendance!$A$1,4,7+(6-1)*4)),"")) | AO35: =IF($AF35="","",IFERROR(AVERAGE(OFFSET(Attendance!$A$1,4,5+(7-1)*4),OFFSET(Attendance!$A$1,4,7+(7-1)*4)),"")) | AP35: =IF($AF35="","",IFERROR(AVERAGE(OFFSET(Attendance!$A$1,4,5+(8-1)*4),OFFSET(Attendance!$A$1,4,7+(8-1)*4)),"")) | AQ35: =IF($AF35="","",IFERROR(AVERAGE(OFFSET(Attendance!$A$1,4,5+(9-1)*4),OFFSET(Attendance!$A$1,4,7+(9-1)*4)),"")) | AR35: =IF($AF35="","",IFERROR(AVERAGE(OFFSET(Attendance!$A$1,4,5+(10-1)*4),OFFSET(Attendance!$A$1,4,7+(10-1)*4)),"")) | AS35: =IF($AF35="","",IFERROR(AVERAGE(OFFSET(Attendance!$A$1,4,5+(11-1)*4),OFFSET(Attendance!$A$1,4,7+(11-1)*4)),"")) | AT35: =IF($AF35="","",IFERROR(AVERAGE(OFFSET(Attendance!$A$1,4,5+(12-1)*4),OFFSET(Attendance!$A$1,4,7+(12-1)*4)),"")) | AU35: =IF($AF35="","",IFERROR(AVERAGE(OFFSET(Attendance!$A$1,4,5+(13-1)*4),OFFSET(Attendance!$A$1,4,7+(13-1)*4)),"")) | AV35: =IF($AF35="","",IFERROR(AVERAGE(OFFSET(Attendance!$A$1,4,5+(14-1)*4),OFFSET(Attendance!$A$1,4,7+(14-1)*4)),"")) | AW35: =IF($AF35="","",IFERROR(AVERAGE(OFFSET(Attendance!$A$1,4,5+(15-1)*4),OFFSET(Attendance!$A$1,4,7+(15-1)*4)),"")) | AX35: =IF($AF35="","",IFERROR(AVERAGE(OFFSET(Attendance!$A$1,4,5+(16-1)*4),OFFSET(Attendance!$A$1,4,7+(16-1)*4)),"")) | AY35: =IF($AF35="","",IFERROR(AVERAGE(OFFSET(Attendance!$A$1,4,5+(17-1)*4),OFFSET(Attendance!$A$1,4,7+(17-1)*4)),"")) | AZ35: =IF($AF35="","",IFERROR(AVERAGE(OFFSET(Attendance!$A$1,4,5+(18-1)*4),OFFSET(Attendance!$A$1,4,7+(18-1)*4)),"")) | BA35: =IF($AF35="","",IFERROR(AVERAGE(OFFSET(Attendance!$A$1,4,5+(19-1)*4),OFFSET(Attendance!$A$1,4,7+(19-1)*4)),"")) | BB35: =IF($AF35="","",IFERROR(AVERAGE(OFFSET(Attendance!$A$1,4,5+(20-1)*4),OFFSET(Attendance!$A$1,4,7+(20-1)*4)),"")) | BC35: =IF($AF35="","",IFERROR(AVERAGE(OFFSET(Attendance!$A$1,4,5+(21-1)*4),OFFSET(Attendance!$A$1,4,7+(21-1)*4)),"")) | BD35: =IF($AF35="","",IFERROR(AVERAGE(OFFSET(Attendance!$A$1,4,5+(22-1)*4),OFFSET(Attendance!$A$1,4,7+(22-1)*4)),"")) | BE35: =IF($AF35="","",IFERROR(Workings!$D6,"")) | BF35: =IF($AF35="","",IFERROR(Workings!$E6,"")) | BG35: =IF($AF35="","",IFERROR(Workings!$G6,"")) | BH35: =IF($AF35="","",IFERROR(Workings!$H6,"")) -> 0
AF36: =IF(Attendance!$D6="","",Attendance!$D6) -> Stella McEvoy | AG36: {=IF($AF36="","",_xlfn.TEXTJOIN("",TRUE,IF(Attendance!$E$4:$CN$4="WR",IFERROR(CHOOSE(Attendance!$E6:$CN6,"▁","▃","▅","▆","█"),"·"),"")))} -> ············································ | AH36: {=IF($AF36="","",_xlfn.TEXTJOIN("",TRUE,IF(Attendance!$CP$4:$FY$4="Rating",IFERROR(CHOOSE(ROUNDUP(Attendance!$CP6:$FY6/2,0),"▁","▃","▅","▆","█"),"·"),"")))} -> ······················ | AI36: =IF($AF36="","",IFERROR(AVERAGE(OFFSET(Attendance!$A$1,5,5+(1-1)*4),OFFSET(Attendance!$A$1,5,7+(1-1)*4)),"")) | AJ36: =IF($AF36="","",IFERROR(AVERAGE(OFFSET(Attendance!$A$1,5,5+(2-1)*4),OFFSET(Attendance!$A$1,5,7+(2-1)*4)),"")) | AK36: =IF($AF36="","",IFERROR(AVERAGE(OFFSET(Attendance!$A$1,5,5+(3-1)*4),OFFSET(Attendance!$A$1,5,7+(3-1)*4)),"")) | AL36: =IF($AF36="","",IFERROR(AVERAGE(OFFSET(Attendance!$A$1,5,5+(4-1)*4),OFFSET(Attendance!$A$1,5,7+(4-1)*4)),"")) | AM36: =IF($AF36="","",IFERROR(AVERAGE(OFFSET(Attendance!$A$1,5,5+(5-1)*4),OFFSET(Attendance!$A$1,5,7+(5-1)*4)),"")) | AN36: =IF($AF36="","",IFERROR(AVERAGE(OFFSET(Attendance!$A$1,5,5+(6-1)*4),OFFSET(Attendance!$A$1,5,7+(6-1)*4)),"")) | AO36: =IF($AF36="","",IFERROR(AVERAGE(OFFSET(Attendance!$A$1,5,5+(7-1)*4),OFFSET(Attendance!$A$1,5,7+(7-1)*4)),"")) | AP36: =IF($AF36="","",IFERROR(AVERAGE(OFFSET(Attendance!$A$1,5,5+(8-1)*4),OFFSET(Attendance!$A$1,5,7+(8-1)*4)),"")) | AQ36: =IF($AF36="","",IFERROR(AVERAGE(OFFSET(Attendance!$A$1,5,5+(9-1)*4),OFFSET(Attendance!$A$1,5,7+(9-1)*4)),"")) | AR36: =IF($AF36="","",IFERROR(AVERAGE(OFFSET(Attendance!$A$1,5,5+(10-1)*4),OFFSET(Attendance!$A$1,5,7+(10-1)*4)),"")) | AS36: =IF($AF36="","",IFERROR(AVERAGE(OFFSET(Attendance!$A$1,5,5+(11-1)*4),OFFSET(Attendance!$A$1,5,7+(11-1)*4)),"")) | AT36: =IF($AF36="","",IFERROR(AVERAGE(OFFSET(Attendance!$A$1,5,5+(12-1)*4),OFFSET(Attendance!$A$1,5,7+(12-1)*4)),"")) | AU36: =IF($AF36="","",IFERROR(AVERAGE(OFFSET(Attendance!$A$1,5,5+(13-1)*4),OFFSET(Attendance!$A$1,5,7+(13-1)*4)),"")) | AV36: =IF($AF36="","",IFERROR(AVERAGE(OFFSET(Attendance!$A$1,5,5+(14-1)*4),OFFSET(Attendance!$A$1,5,7+(14-1)*4)),"")) | AW36: =IF($AF36="","",IFERROR(AVERAGE(OFFSET(Attendance!$A$1,5,5+(15-1)*4),OFFSET(Attendance!$A$1,5,7+(15-1)*4)),"")) | AX36: =IF($AF36="","",IFERROR(AVERAGE(OFFSET(Attendance!$A$1,5,5+(16-1)*4),OFFSET(Attendance!$A$1,5,7+(16-1)*4)),"")) | AY36: =IF($AF36="","",IFERROR(AVERAGE(OFFSET(Attendance!$A$1,5,5+(17-1)*4),OFFSET(Attendance!$A$1,5,7+(17-1)*4)),"")) | AZ36: =IF($AF36="","",IFERROR(AVERAGE(OFFSET(Attendance!$A$1,5,5+(18-1)*4),OFFSET(Attendance!$A$1,5,7+(18-1)*4)),"")) | BA36: =IF($AF36="","",IFERROR(AVERAGE(OFFSET(Attendance!$A$1,5,5+(19-1)*4),OFFSET(Attendance!$A$1,5,7+(19-1)*4)),"")) | BB36: =IF($AF36="","",IFERROR(AVERAGE(OFFSET(Attendance!$A$1,5,5+(20-1)*4),OFFSET(Attendance!$A$1,5,7+(20-1)*4)),"")) | BC36: =IF($AF36="","",IFERROR(AVERAGE(OFFSET(Attendance!$A$1,5,5+(21-1)*4),OFFSET(Attendance!$A$1,5,7+(21-1)*4)),"")) | BD36: =IF($AF36="","",IFERROR(AVERAGE(OFFSET(Attendance!$A$1,5,5+(22-1)*4),OFFSET(Attendance!$A$1,5,7+(22-1)*4)),"")) | BE36: =IF($AF36="","",IFERROR(Workings!$D7,"")) | BF36: =IF($AF36="","",IFERROR(Workings!$E7,"")) | BG36: =IF($AF36="","",IFERROR(Workings!$G7,"")) | BH36: =IF($AF36="","",IFERROR(Workings!$H7,"")) -> 0
AF37: =IF(Attendance!$D7="","",Attendance!$D7) -> Zara Power | AG37: {=IF($AF37="","",_xlfn.TEXTJOIN("",TRUE,IF(Attendance!$E$4:$CN$4="WR",IFERROR(CHOOSE(Attendance!$E7:$CN7,"▁","▃","▅","▆","█"),"·"),"")))} -> ············································ | AH37: {=IF($AF37="","",_xlfn.TEXTJOIN("",TRUE,IF(Attendance!$CP$4:$FY$4="Rating",IFERROR(CHOOSE(ROUNDUP(Attendance!$CP7:$FY7/2,0),"▁","▃","▅","▆","█"),"·"),"")))} -> ······················ | AI37: =IF($AF37="","",IFERROR(AVERAGE(OFFSET(Attendance!$A$1,6,5+(1-1)*4),OFFSET(Attendance!$A$1,6,7+(1-1)*4)),"")) | AJ37: =IF($AF37="","",IFERROR(AVERAGE(OFFSET(Attendance!$A$1,6,5+(2-1)*4),OFFSET(Attendance!$A$1,6,7+(2-1)*4)),"")) | AK37: =IF($AF37="","",IFERROR(AVERAGE(OFFSET(Attendance!$A$1,6,5+(3-1)*4),OFFSET(Attendance!$A$1,6,7+(3-1)*4)),"")) | AL37: =IF($AF37="","",IFERROR(AVERAGE(OFFSET(Attendance!$A$1,6,5+(4-1)*4),OFFSET(Attendance!$A$1,6,7+(4-1)*4)),"")) | AM37: =IF($AF37="","",IFERROR(AVERAGE(OFFSET(Attendance!$A$1,6,5+(5-1)*4),OFFSET(Attendance!$A$1,6,7+(5-1)*4)),"")) | AN37: =IF($AF37="","",IFERROR(AVERAGE(OFFSET(Attendance!$A$1,6,5+(6-1)*4),OFFSET(Attendance!$A$1,6,7+(6-1)*4)),"")) | AO37: =IF($AF37="","",IFERROR(AVERAGE(OFFSET(Attendance!$A$1,6,5+(7-1)*4),OFFSET(Attendance!$A$1,6,7+(7-1)*4)),"")) | AP37: =IF($AF37="","",IFERROR(AVERAGE(OFFSET(Attendance!$A$1,6,5+(8-1)*4),OFFSET(Attendance!$A$1,6,7+(8-1)*4)),"")) | AQ37: =IF($AF37="","",IFERROR(AVERAGE(OFFSET(Attendance!$A$1,6,5+(9-1)*4),OFFSET(Attendance!$A$1,6,7+(9-1)*4)),"")) | AR37: =IF($AF37="","",IFERROR(AVERAGE(OFFSET(Attendance!$A$1,6,5+(10-1)*4),OFFSET(Attendance!$A$1,6,7+(10-1)*4)),"")) | AS37: =IF($AF37="","",IFERROR(AVERAGE(OFFSET(Attendance!$A$1,6,5+(11-1)*4),OFFSET(Attendance!$A$1,6,7+(11-1)*4)),"")) | AT37: =IF($AF37="","",IFERROR(AVERAGE(OFFSET(Attendance!$A$1,6,5+(12-1)*4),OFFSET(Attendance!$A$1,6,7+(12-1)*4)),"")) | AU37: =IF($AF37="","",IFERROR(AVERAGE(OFFSET(Attendance!$A$1,6,5+(13-1)*4),OFFSET(Attendance!$A$1,6,7+(13-1)*4)),"")) | AV37: =IF($AF37="","",IFERROR(AVERAGE(OFFSET(Attendance!$A$1,6,5+(14-1)*4),OFFSET(Attendance!$A$1,6,7+(14-1)*4)),"")) | AW37: =IF($AF37="","",IFERROR(AVERAGE(OFFSET(Attendance!$A$1,6,5+(15-1)*4),OFFSET(Attendance!$A$1,6,7+(15-1)*4)),"")) | AX37: =IF($AF37="","",IFERROR(AVERAGE(OFFSET(Attendance!$A$1,6,5+(16-1)*4),OFFSET(Attendance!$A$1,6,7+(16-1)*4)),"")) | AY37: =IF($AF37="","",IFERROR(AVERAGE(OFFSET(Attendance!$A$1,6,5+(17-1)*4),OFFSET(Attendance!$A$1,6,7+(17-1)*4)),"")) | AZ37: =IF($AF37="","",IFERROR(AVERAGE(OFFSET(Attendance!$A$1,6,5+(18-1)*4),OFFSET(Attendance!$A$1,6,7+(18-1)*4)),"")) | BA37: =IF($AF37="","",IFERROR(AVERAGE(OFFSET(Attendance!$A$1,6,5+(19-1)*4),OFFSET(Attendance!$A$1,6,7+(19-1)*4)),"")) | BB37: =IF($AF37="","",IFERROR(AVERAGE(OFFSET(Attendance!$A$1,6,5+(20-1)*4),OFFSET(Attendance!$A$1,6,7+(20-1)*4)),"")) | BC37: =IF($AF37="","",IFERROR(AVERAGE(OFFSET(Attendance!$A$1,6,5+(21-1)*4),OFFSET(Attendance!$A$1,6,7+(21-1)*4)),"")) | BD37: =IF($AF37="","",IFERROR(AVERAGE(OFFSET(Attendance!$A$1,6,5+(22-1)*4),OFFSET(Attendance!$A$1,6,7+(22-1)*4)),"")) | BE37: =IF($AF37="","",IFERROR(Workings!$D8,"")) | BF37: =IF($AF37="","",IFERROR(Workings!$E8,"")) | BG37: =IF($AF37="","",IFERROR(Workings!$G8,"")) | BH37: =IF($AF37="","",IFERROR(Workings!$H8,"")) -> 0
AF38: =IF(Attendance!$D8="","",Attendance!$D8) -> Heidi Cerubini Dunne | AG38: {=IF($AF38="","",_xlfn.TEXTJOIN("",TRUE,IF(Attendance!$E$4:$CN$4="WR",IFERROR(CHOOSE(Attendance!$E8:$CN8,"▁","▃","▅","▆","█"),"·"),"")))} -> ············································ | AH38: {=IF($AF38="","",_xlfn.TEXTJOIN("",TRUE,IF(Attendance!$CP$4:$FY$4="Rating",IFERROR(CHOOSE(ROUNDUP(Attendance!$CP8:$FY8/2,0),"▁","▃","▅","▆","█"),"·"),"")))} -> ······················ | AI38: =IF($AF38="","",IFERROR(AVERAGE(OFFSET(Attendance!$A$1,7,5+(1-1)*4),OFFSET(Attendance!$A$1,7,7+(1-1)*4)),"")) | AJ38: =IF($AF38="","",IFERROR(AVERAGE(OFFSET(Attendance!$A$1,7,5+(2-1)*4),OFFSET(Attendance!$A$1,7,7+(2-1)*4)),"")) | AK38: =IF($AF38="","",IFERROR(AVERAGE(OFFSET(Attendance!$A$1,7,5+(3-1)*4),OFFSET(Attendance!$A$1,7,7+(3-1)*4)),"")) | AL38: =IF($AF38="","",IFERROR(AVERAGE(OFFSET(Attendance!$A$1,7,5+(4-1)*4),OFFSET(Attendance!$A$1,7,7+(4-1)*4)),"")) | AM38: =IF($AF38="","",IFERROR(AVERAGE(OFFSET(Attendance!$A$1,7,5+(5-1)*4),OFFSET(Attendance!$A$1,7,7+(5-1)*4)),"")) | AN38: =IF($AF38="","",IFERROR(AVERAGE(OFFSET(Attendance!$A$1,7,5+(6-1)*4),OFFSET(Attendance!$A$1,7,7+(6-1)*4)),"")) | AO38: =IF($AF38="","",IFERROR(AVERAGE(OFFSET(Attendance!$A$1,7,5+(7-1)*4),OFFSET(Attendance!$A$1,7,7+(7-1)*4)),"")) | AP38: =IF($AF38="","",IFERROR(AVERAGE(OFFSET(Attendance!$A$1,7,5+(8-1)*4),OFFSET(Attendance!$A$1,7,7+(8-1)*4)),"")) | AQ38: =IF($AF38="","",IFERROR(AVERAGE(OFFSET(Attendance!$A$1,7,5+(9-1)*4),OFFSET(Attendance!$A$1,7,7+(9-1)*4)),"")) | AR38: =IF($AF38="","",IFERROR(AVERAGE(OFFSET(Attendance!$A$1,7,5+(10-1)*4),OFFSET(Attendance!$A$1,7,7+(10-1)*4)),"")) | AS38: =IF($AF38="","",IFERROR(AVERAGE(OFFSET(Attendance!$A$1,7,5+(11-1)*4),OFFSET(Attendance!$A$1,7,7+(11-1)*4)),"")) | AT38: =IF($AF38="","",IFERROR(AVERAGE(OFFSET(Attendance!$A$1,7,5+(12-1)*4),OFFSET(Attendance!$A$1,7,7+(12-1)*4)),"")) | AU38: =IF($AF38="","",IFERROR(AVERAGE(OFFSET(Attendance!$A$1,7,5+(13-1)*4),OFFSET(Attendance!$A$1,7,7+(13-1)*4)),"")) | AV38: =IF($AF38="","",IFERROR(AVERAGE(OFFSET(Attendance!$A$1,7,5+(14-1)*4),OFFSET(Attendance!$A$1,7,7+(14-1)*4)),"")) | AW38: =IF($AF38="","",IFERROR(AVERAGE(OFFSET(Attendance!$A$1,7,5+(15-1)*4),OFFSET(Attendance!$A$1,7,7+(15-1)*4)),"")) | AX38: =IF($AF38="","",IFERROR(AVERAGE(OFFSET(Attendance!$A$1,7,5+(16-1)*4),OFFSET(Attendance!$A$1,7,7+(16-1)*4)),"")) | AY38: =IF($AF38="","",IFERROR(AVERAGE(OFFSET(Attendance!$A$1,7,5+(17-1)*4),OFFSET(Attendance!$A$1,7,7+(17-1)*4)),"")) | AZ38: =IF($AF38="","",IFERROR(AVERAGE(OFFSET(Attendance!$A$1,7,5+(18-1)*4),OFFSET(Attendance!$A$1,7,7+(18-1)*4)),"")) | BA38: =IF($AF38="","",IFERROR(AVERAGE(OFFSET(Attendance!$A$1,7,5+(19-1)*4),OFFSET(Attendance!$A$1,7,7+(19-1)*4)),"")) | BB38: =IF($AF38="","",IFERROR(AVERAGE(OFFSET(Attendance!$A$1,7,5+(20-1)*4),OFFSET(Attendance!$A$1,7,7+(20-1)*4)),"")) | BC38: =IF($AF38="","",IFERROR(AVERAGE(OFFSET(Attendance!$A$1,7,5+(21-1)*4),OFFSET(Attendance!$A$1,7,7+(21-1)*4)),"")) | BD38: =IF($AF38="","",IFERROR(AVERAGE(OFFSET(Attendance!$A$1,7,5+(22-1)*4),OFFSET(Attendance!$A$1,7,7+(22-1)*4)),"")) | BE38: =IF($AF38="","",IFERROR(Workings!$D9,"")) | BF38: =IF($AF38="","",IFERROR(Workings!$E9,"")) | BG38: =IF($AF38="","",IFERROR(Workings!$G9,"")) | BH38: =IF($AF38="","",IFERROR(Workings!$H9,"")) -> 0
AF39: =IF(Attendance!$D9="","",Attendance!$D9) -> Roisin Offenhausen | AG39: {=IF($AF39="","",_xlfn.TEXTJOIN("",TRUE,IF(Attendance!$E$4:$CN$4="WR",IFERROR(CHOOSE(Attendance!$E9:$CN9,"▁","▃","▅","▆","█"),"·"),"")))} -> ············································ | AH39: {=IF($AF39="","",_xlfn.TEXTJOIN("",TRUE,IF(Attendance!$CP$4:$FY$4="Rating",IFERROR(CHOOSE(ROUNDUP(Attendance!$CP9:$FY9/2,0),"▁","▃","▅","▆","█"),"·"),"")))} -> ······················ | AI39: =IF($AF39="","",IFERROR(AVERAGE(OFFSET(Attendance!$A$1,8,5+(1-1)*4),OFFSET(Attendance!$A$1,8,7+(1-1)*4)),"")) | AJ39: =IF($AF39="","",IFERROR(AVERAGE(OFFSET(Attendance!$A$1,8,5+(2-1)*4),OFFSET(Attendance!$A$1,8,7+(2-1)*4)),"")) | AK39: =IF($AF39="","",IFERROR(AVERAGE(OFFSET(Attendance!$A$1,8,5+(3-1)*4),OFFSET(Attendance!$A$1,8,7+(3-1)*4)),"")) | AL39: =IF($AF39="","",IFERROR(AVERAGE(OFFSET(Attendance!$A$1,8,5+(4-1)*4),OFFSET(Attendance!$A$1,8,7+(4-1)*4)),"")) | AM39: =IF($AF39="","",IFERROR(AVERAGE(OFFSET(Attendance!$A$1,8,5+(5-1)*4),OFFSET(Attendance!$A$1,8,7+(5-1)*4)),"")) | AN39: =IF($AF39="","",IFERROR(AVERAGE(OFFSET(Attendance!$A$1,8,5+(6-1)*4),OFFSET(Attendance!$A$1,8,7+(6-1)*4)),"")) | AO39: =IF($AF39="","",IFERROR(AVERAGE(OFFSET(Attendance!$A$1,8,5+(7-1)*4),OFFSET(Attendance!$A$1,8,7+(7-1)*4)),"")) | AP39: =IF($AF39="","",IFERROR(AVERAGE(OFFSET(Attendance!$A$1,8,5+(8-1)*4),OFFSET(Attendance!$A$1,8,7+(8-1)*4)),"")) | AQ39: =IF($AF39="","",IFERROR(AVERAGE(OFFSET(Attendance!$A$1,8,5+(9-1)*4),OFFSET(Attendance!$A$1,8,7+(9-1)*4)),"")) | AR39: =IF($AF39="","",IFERROR(AVERAGE(OFFSET(Attendance!$A$1,8,5+(10-1)*4),OFFSET(Attendance!$A$1,8,7+(10-1)*4)),"")) | AS39: =IF($AF39="","",IFERROR(AVERAGE(OFFSET(Attendance!$A$1,8,5+(11-1)*4),OFFSET(Attendance!$A$1,8,7+(11-1)*4)),"")) | AT39: =IF($AF39="","",IFERROR(AVERAGE(OFFSET(Attendance!$A$1,8,5+(12-1)*4),OFFSET(Attendance!$A$1,8,7+(12-1)*4)),"")) | AU39: =IF($AF39="","",IFERROR(AVERAGE(OFFSET(Attendance!$A$1,8,5+(13-1)*4),OFFSET(Attendance!$A$1,8,7+(13-1)*4)),"")) | AV39: =IF($AF39="","",IFERROR(AVERAGE(OFFSET(Attendance!$A$1,8,5+(14-1)*4),OFFSET(Attendance!$A$1,8,7+(14-1)*4)),"")) | AW39: =IF($AF39="","",IFERROR(AVERAGE(OFFSET(Attendance!$A$1,8,5+(15-1)*4),OFFSET(Attendance!$A$1,8,7+(15-1)*4)),"")) | AX39: =IF($AF39="","",IFERROR(AVERAGE(OFFSET(Attendance!$A$1,8,5+(16-1)*4),OFFSET(Attendance!$A$1,8,7+(16-1)*4)),"")) | AY39: =IF($AF39="","",IFERROR(AVERAGE(OFFSET(Attendance!$A$1,8,5+(17-1)*4),OFFSET(Attendance!$A$1,8,7+(17-1)*4)),"")) | AZ39: =IF($AF39="","",IFERROR(AVERAGE(OFFSET(Attendance!$A$1,8,5+(18-1)*4),OFFSET(Attendance!$A$1,8,7+(18-1)*4)),"")) | BA39: =IF($AF39="","",IFERROR(AVERAGE(OFFSET(Attendance!$A$1,8,5+(19-1)*4),OFFSET(Attendance!$A$1,8,7+(19-1)*4)),"")) | BB39: =IF($AF39="","",IFERROR(AVERAGE(OFFSET(Attendance!$A$1,8,5+(20-1)*4),OFFSET(Attendance!$A$1,8,7+(20-1)*4)),"")) | BC39: =IF($AF39="","",IFERROR(AVERAGE(OFFSET(Attendance!$A$1,8,5+(21-1)*4),OFFSET(Attendance!$A$1,8,7+(21-1)*4)),"")) | BD39: =IF($AF39="","",IFERROR(AVERAGE(OFFSET(Attendance!$A$1,8,5+(22-1)*4),OFFSET(Attendance!$A$1,8,7+(22-1)*4)),"")) | BE39: =IF($AF39="","",IFERROR(Workings!$D10,"")) | BF39: =IF($AF39="","",IFERROR(Workings!$E10,"")) | BG39: =IF($AF39="","",IFERROR(Workings!$G10,"")) | BH39: =IF($AF39="","",IFERROR(Workings!$H10,"")) -> 0
AF40: =IF(Attendance!$D10="","",Attendance!$D10) -> Naomi Adewoyin | AG40: {=IF($AF40="","",_xlfn.TEXTJOIN("",TRUE,IF(Attendance!$E$4:$CN$4="WR",IFERROR(CHOOSE(Attendance!$E10:$CN10,"▁","▃","▅","▆","█"),"·"),"")))} -> ············································ | AH40: {=IF($AF40="","",_xlfn.TEXTJOIN("",TRUE,IF(Attendance!$CP$4:$FY$4="Rating",IFERROR(CHOOSE(ROUNDUP(Attendance!$CP10:$FY10/2,0),"▁","▃","▅","▆","█"),"·"),"")))} -> ······················ | AI40: =IF($AF40="","",IFERROR(AVERAGE(OFFSET(Attendance!$A$1,9,5+(1-1)*4),OFFSET(Attendance!$A$1,9,7+(1-1)*4)),"")) | AJ40: =IF($AF40="","",IFERROR(AVERAGE(OFFSET(Attendance!$A$1,9,5+(2-1)*4),OFFSET(Attendance!$A$1,9,7+(2-1)*4)),"")) | AK40: =IF($AF40="","",IFERROR(AVERAGE(OFFSET(Attendance!$A$1,9,5+(3-1)*4),OFFSET(Attendance!$A$1,9,7+(3-1)*4)),"")) | AL40: =IF($AF40="","",IFERROR(AVERAGE(OFFSET(Attendance!$A$1,9,5+(4-1)*4),OFFSET(Attendance!$A$1,9,7+(4-1)*4)),"")) | AM40: =IF($AF40="","",IFERROR(AVERAGE(OFFSET(Attendance!$A$1,9,5+(5-1)*4),OFFSET(Attendance!$A$1,9,7+(5-1)*4)),"")) | AN40: =IF($AF40="","",IFERROR(AVERAGE(OFFSET(Attendance!$A$1,9,5+(6-1)*4),OFFSET(Attendance!$A$1,9,7+(6-1)*4)),"")) | AO40: =IF($AF40="","",IFERROR(AVERAGE(OFFSET(Attendance!$A$1,9,5+(7-1)*4),OFFSET(Attendance!$A$1,9,7+(7-1)*4)),"")) | AP40: =IF($AF40="","",IFERROR(AVERAGE(OFFSET(Attendance!$A$1,9,5+(8-1)*4),OFFSET(Attendance!$A$1,9,7+(8-1)*4)),"")) | AQ40: =IF($AF40="","",IFERROR(AVERAGE(OFFSET(Attendance!$A$1,9,5+(9-1)*4),OFFSET(Attendance!$A$1,9,7+(9-1)*4)),"")) | AR40: =IF($AF40="","",IFERROR(AVERAGE(OFFSET(Attendance!$A$1,9,5+(10-1)*4),OFFSET(Attendance!$A$1,9,7+(10-1)*4)),"")) | AS40: =IF($AF40="","",IFERROR(AVERAGE(OFFSET(Attendance!$A$1,9,5+(11-1)*4),OFFSET(Attendance!$A$1,9,7+(11-1)*4)),"")) | AT40: =IF($AF40="","",IFERROR(AVERAGE(OFFSET(Attendance!$A$1,9,5+(12-1)*4),OFFSET(Attendance!$A$1,9,7+(12-1)*4)),"")) | AU40: =IF($AF40="","",IFERROR(AVERAGE(OFFSET(Attendance!$A$1,9,5+(13-1)*4),OFFSET(Attendance!$A$1,9,7+(13-1)*4)),"")) | AV40: =IF($AF40="","",IFERROR(AVERAGE(OFFSET(Attendance!$A$1,9,5+(14-1)*4),OFFSET(Attendance!$A$1,9,7+(14-1)*4)),"")) | AW40: =IF($AF40="","",IFERROR(AVERAGE(OFFSET(Attendance!$A$1,9,5+(15-1)*4),OFFSET(Attendance!$A$1,9,7+(15-1)*4)),"")) | AX40: =IF($AF40="","",IFERROR(AVERAGE(OFFSET(Attendance!$A$1,9,5+(16-1)*4),OFFSET(Attendance!$A$1,9,7+(16-1)*4)),"")) | AY40: =IF($AF40="","",IFERROR(AVERAGE(OFFSET(Attendance!$A$1,9,5+(17-1)*4),OFFSET(Attendance!$A$1,9,7+(17-1)*4)),"")) | AZ40: =IF($AF40="","",IFERROR(AVERAGE(OFFSET(Attendance!$A$1,9,5+(18-1)*4),OFFSET(Attendance!$A$1,9,7+(18-1)*4)),"")) | BA40: =IF($AF40="","",IFERROR(AVERAGE(OFFSET(Attendance!$A$1,9,5+(19-1)*4),OFFSET(Attendance!$A$1,9,7+(19-1)*4)),"")) | BB40: =IF($AF40="","",IFERROR(AVERAGE(OFFSET(Attendance!$A$1,9,5+(20-1)*4),OFFSET(Attendance!$A$1,9,7+(20-1)*4)),"")) | BC40: =IF($AF40="","",IFERROR(AVERAGE(OFFSET(Attendance!$A$1,9,5+(21-1)*4),OFFSET(Attendance!$A$1,9,7+(21-1)*4)),"")) | BD40: =IF($AF40="","",IFERROR(AVERAGE(OFFSET(Attendance!$A$1,9,5+(22-1)*4),OFFSET(Attendance!$A$1,9,7+(22-1)*4)),"")) | BE40: =IF($AF40="","",IFERROR(Workings!$D11,"")) | BF40: =IF($AF40="","",IFERROR(Workings!$E11,"")) | BG40: =IF($AF40="","",IFERROR(Workings!$G11,"")) | BH40: =IF($AF40="","",IFERROR(Workings!$H11,"")) -> 0
AF41: =IF(Attendance!$D11="","",Attendance!$D11) -> Amber Kilalee | AG41: {=IF($AF41="","",_xlfn.TEXTJOIN("",TRUE,IF(Attendance!$E$4:$CN$4="WR",IFERROR(CHOOSE(Attendance!$E11:$CN11,"▁","▃","▅","▆","█"),"·"),"")))} -> ············································ | AH41: {=IF($AF41="","",_xlfn.TEXTJOIN("",TRUE,IF(Attendance!$CP$4:$FY$4="Rating",IFERROR(CHOOSE(ROUNDUP(Attendance!$CP11:$FY11/2,0),"▁","▃","▅","▆","█"),"·"),"")))} -> ······················ | AI41: =IF($AF41="","",IFERROR(AVERAGE(OFFSET(Attendance!$A$1,10,5+(1-1)*4),OFFSET(Attendance!$A$1,10,7+(1-1)*4)),"")) | AJ41: =IF($AF41="","",IFERROR(AVERAGE(OFFSET(Attendance!$A$1,10,5+(2-1)*4),OFFSET(Attendance!$A$1,10,7+(2-1)*4)),"")) | AK41: =IF($AF41="","",IFERROR(AVERAGE(OFFSET(Attendance!$A$1,10,5+(3-1)*4),OFFSET(Attendance!$A$1,10,7+(3-1)*4)),"")) | AL41: =IF($AF41="","",IFERROR(AVERAGE(OFFSET(Attendance!$A$1,10,5+(4-1)*4),OFFSET(Attendance!$A$1,10,7+(4-1)*4)),"")) | AM41: =IF($AF41="","",IFERROR(AVERAGE(OFFSET(Attendance!$A$1,10,5+(5-1)*4),OFFSET(Attendance!$A$1,10,7+(5-1)*4)),"")) | AN41: =IF($AF41="","",IFERROR(AVERAGE(OFFSET(Attendance!$A$1,10,5+(6-1)*4),OFFSET(Attendance!$A$1,10,7+(6-1)*4)),"")) | AO41: =IF($AF41="","",IFERROR(AVERAGE(OFFSET(Attendance!$A$1,10,5+(7-1)*4),OFFSET(Attendance!$A$1,10,7+(7-1)*4)),"")) | AP41: =IF($AF41="","",IFERROR(AVERAGE(OFFSET(Attendance!$A$1,10,5+(8-1)*4),OFFSET(Attendance!$A$1,10,7+(8-1)*4)),"")) | AQ41: =IF($AF41="","",IFERROR(AVERAGE(OFFSET(Attendance!$A$1,10,5+(9-1)*4),OFFSET(Attendance!$A$1,10,7+(9-1)*4)),"")) | AR41: =IF($AF41="","",IFERROR(AVERAGE(OFFSET(Attendance!$A$1,10,5+(10-1)*4),OFFSET(Attendance!$A$1,10,7+(10-1)*4)),"")) | AS41: =IF($AF41="","",IFERROR(AVERAGE(OFFSET(Attendance!$A$1,10,5+(11-1)*4),OFFSET(Attendance!$A$1,10,7+(11-1)*4)),"")) | AT41: =IF($AF41="","",IFERROR(AVERAGE(OFFSET(Attendance!$A$1,10,5+(12-1)*4),OFFSET(Attendance!$A$1,10,7+(12-1)*4)),"")) | AU41: =IF($AF41="","",IFERROR(AVERAGE(OFFSET(Attendance!$A$1,10,5+(13-1)*4),OFFSET(Attendance!$A$1,10,7+(13-1)*4)),"")) | AV41: =IF($AF41="","",IFERROR(AVERAGE(OFFSET(Attendance!$A$1,10,5+(14-1)*4),OFFSET(Attendance!$A$1,10,7+(14-1)*4)),"")) | AW41: =IF($AF41="","",IFERROR(AVERAGE(OFFSET(Attendance!$A$1,10,5+(15-1)*4),OFFSET(Attendance!$A$1,10,7+(15-1)*4)),"")) | AX41: =IF($AF41="","",IFERROR(AVERAGE(OFFSET(Attendance!$A$1,10,5+(16-1)*4),OFFSET(Attendance!$A$1,10,7+(16-1)*4)),"")) | AY41: =IF($AF41="","",IFERROR(AVERAGE(OFFSET(Attendance!$A$1,10,5+(17-1)*4),OFFSET(Attendance!$A$1,10,7+(17-1)*4)),"")) | AZ41: =IF($AF41="","",IFERROR(AVERAGE(OFFSET(Attendance!$A$1,10,5+(18-1)*4),OFFSET(Attendance!$A$1,10,7+(18-1)*4)),"")) | BA41: =IF($AF41="","",IFERROR(AVERAGE(OFFSET(Attendance!$A$1,10,5+(19-1)*4),OFFSET(Attendance!$A$1,10,7+(19-1)*4)),"")) | BB41: =IF($AF41="","",IFERROR(AVERAGE(OFFSET(Attendance!$A$1,10,5+(20-1)*4),OFFSET(Attendance!$A$1,10,7+(20-1)*4)),"")) | BC41: =IF($AF41="","",IFERROR(AVERAGE(OFFSET(Attendance!$A$1,10,5+(21-1)*4),OFFSET(Attendance!$A$1,10,7+(21-1)*4)),"")) | BD41: =IF($AF41="","",IFERROR(AVERAGE(OFFSET(Attendance!$A$1,10,5+(22-1)*4),OFFSET(Attendance!$A$1,10,7+(22-1)*4)),"")) | BE41: =IF($AF41="","",IFERROR(Workings!$D12,"")) | BF41: =IF($AF41="","",IFERROR(Workings!$E12,"")) | BG41: =IF($AF41="","",IFERROR(Workings!$G12,"")) | BH41: =IF($AF41="","",IFERROR(Workings!$H12,"")) -> 0
AF42: =IF(Attendance!$D12="","",Attendance!$D12) -> Shauna Kavanagh | AG42: {=IF($AF42="","",_xlfn.TEXTJOIN("",TRUE,IF(Attendance!$E$4:$CN$4="WR",IFERROR(CHOOSE(Attendance!$E12:$CN12,"▁","▃","▅","▆","█"),"·"),"")))} -> ············································ | AH42: {=IF($AF42="","",_xlfn.TEXTJOIN("",TRUE,IF(Attendance!$CP$4:$FY$4="Rating",IFERROR(CHOOSE(ROUNDUP(Attendance!$CP12:$FY12/2,0),"▁","▃","▅","▆","█"),"·"),"")))} -> ······················ | AI42: =IF($AF42="","",IFERROR(AVERAGE(OFFSET(Attendance!$A$1,11,5+(1-1)*4),OFFSET(Attendance!$A$1,11,7+(1-1)*4)),"")) | AJ42: =IF($AF42="","",IFERROR(AVERAGE(OFFSET(Attendance!$A$1,11,5+(2-1)*4),OFFSET(Attendance!$A$1,11,7+(2-1)*4)),"")) | AK42: =IF($AF42="","",IFERROR(AVERAGE(OFFSET(Attendance!$A$1,11,5+(3-1)*4),OFFSET(Attendance!$A$1,11,7+(3-1)*4)),"")) | AL42: =IF($AF42="","",IFERROR(AVERAGE(OFFSET(Attendance!$A$1,11,5+(4-1)*4),OFFSET(Attendance!$A$1,11,7+(4-1)*4)),"")) | AM42: =IF($AF42="","",IFERROR(AVERAGE(OFFSET(Attendance!$A$1,11,5+(5-1)*4),OFFSET(Attendance!$A$1,11,7+(5-1)*4)),"")) | AN42: =IF($AF42="","",IFERROR(AVERAGE(OFFSET(Attendance!$A$1,11,5+(6-1)*4),OFFSET(Attendance!$A$1,11,7+(6-1)*4)),"")) | AO42: =IF($AF42="","",IFERROR(AVERAGE(OFFSET(Attendance!$A$1,11,5+(7-1)*4),OFFSET(Attendance!$A$1,11,7+(7-1)*4)),"")) | AP42: =IF($AF42="","",IFERROR(AVERAGE(OFFSET(Attendance!$A$1,11,5+(8-1)*4),OFFSET(Attendance!$A$1,11,7+(8-1)*4)),"")) | AQ42: =IF($AF42="","",IFERROR(AVERAGE(OFFSET(Attendance!$A$1,11,5+(9-1)*4),OFFSET(Attendance!$A$1,11,7+(9-1)*4)),"")) | AR42: =IF($AF42="","",IFERROR(AVERAGE(OFFSET(Attendance!$A$1,11,5+(10-1)*4),OFFSET(Attendance!$A$1,11,7+(10-1)*4)),"")) | AS42: =IF($AF42="","",IFERROR(AVERAGE(OFFSET(Attendance!$A$1,11,5+(11-1)*4),OFFSET(Attendance!$A$1,11,7+(11-1)*4)),"")) | AT42: =IF($AF42="","",IFERROR(AVERAGE(OFFSET(Attendance!$A$1,11,5+(12-1)*4),OFFSET(Attendance!$A$1,11,7+(12-1)*4)),"")) | AU42: =IF($AF42="","",IFERROR(AVERAGE(OFFSET(Attendance!$A$1,11,5+(13-1)*4),OFFSET(Attendance!$A$1,11,7+(13-1)*4)),"")) | AV42: =IF($AF42="","",IFERROR(AVERAGE(OFFSET(Attendance!$A$1,11,5+(14-1)*4),OFFSET(Attendance!$A$1,11,7+(14-1)*4)),"")) | AW42: =IF($AF42="","",IFERROR(AVERAGE(OFFSET(Attendance!$A$1,11,5+(15-1)*4),OFFSET(Attendance!$A$1,11,7+(15-1)*4)),"")) | AX42: =IF($AF42="","",IFERROR(AVERAGE(OFFSET(Attendance!$A$1,11,5+(16-1)*4),OFFSET(Attendance!$A$1,11,7+(16-1)*4)),"")) | AY42: =IF($AF42="","",IFERROR(AVERAGE(OFFSET(Attendance!$A$1,11,5+(17-1)*4),OFFSET(Attendance!$A$1,11,7+(17-1)*4)),"")) | AZ42: =IF($AF42="","",IFERROR(AVERAGE(OFFSET(Attendance!$A$1,11,5+(18-1)*4),OFFSET(Attendance!$A$1,11,7+(18-1)*4)),"")) | BA42: =IF($AF42="","",IFERROR(AVERAGE(OFFSET(Attendance!$A$1,11,5+(19-1)*4),OFFSET(Attendance!$A$1,11,7+(19-1)*4)),"")) | BB42: =IF($AF42="","",IFERROR(AVERAGE(OFFSET(Attendance!$A$1,11,5+(20-1)*4),OFFSET(Attendance!$A$1,11,7+(20-1)*4)),"")) | BC42: =IF($AF42="","",IFERROR(AVERAGE(OFFSET(Attendance!$A$1,11,5+(21-1)*4),OFFSET(Attendance!$A$1,11,7+(21-1)*4)),"")) | BD42: =IF($AF42="","",IFERROR(AVERAGE(OFFSET(Attendance!$A$1,11,5+(22-1)*4),OFFSET(Attendance!$A$1,11,7+(22-1)*4)),"")) | BE42: =IF($AF42="","",IFERROR(Workings!$D13,"")) | BF42: =IF($AF42="","",IFERROR(Workings!$E13,"")) | BG42: =IF($AF42="","",IFERROR(Workings!$G13,"")) | BH42: =IF($AF42="","",IFERROR(Workings!$H13,"")) -> 0
AF43: =IF(Attendance!$D13="","",Attendance!$D13) -> Tara Brannigan | AG43: {=IF($AF43="","",_xlfn.TEXTJOIN("",TRUE,IF(Attendance!$E$4:$CN$4="WR",IFERROR(CHOOSE(Attendance!$E13:$CN13,"▁","▃","▅","▆","█"),"·"),"")))} -> ············································ | AH43: {=IF($AF43="","",_xlfn.TEXTJOIN("",TRUE,IF(Attendance!$CP$4:$FY$4="Rating",IFERROR(CHOOSE(ROUNDUP(Attendance!$CP13:$FY13/2,0),"▁","▃","▅","▆","█"),"·"),"")))} -> ······················ | AI43: =IF($AF43="","",IFERROR(AVERAGE(OFFSET(Attendance!$A$1,12,5+(1-1)*4),OFFSET(Attendance!$A$1,12,7+(1-1)*4)),"")) | AJ43: =IF($AF43="","",IFERROR(AVERAGE(OFFSET(Attendance!$A$1,12,5+(2-1)*4),OFFSET(Attendance!$A$1,12,7+(2-1)*4)),"")) | AK43: =IF($AF43="","",IFERROR(AVERAGE(OFFSET(Attendance!$A$1,12,5+(3-1)*4),OFFSET(Attendance!$A$1,12,7+(3-1)*4)),"")) | AL43: =IF($AF43="","",IFERROR(AVERAGE(OFFSET(Attendance!$A$1,12,5+(4-1)*4),OFFSET(Attendance!$A$1,12,7+(4-1)*4)),"")) | AM43: =IF($AF43="","",IFERROR(AVERAGE(OFFSET(Attendance!$A$1,12,5+(5-1)*4),OFFSET(Attendance!$A$1,12,7+(5-1)*4)),"")) | AN43: =IF($AF43="","",IFERROR(AVERAGE(OFFSET(Attendance!$A$1,12,5+(6-1)*4),OFFSET(Attendance!$A$1,12,7+(6-1)*4)),"")) | AO43: =IF($AF43="","",IFERROR(AVERAGE(OFFSET(Attendance!$A$1,12,5+(7-1)*4),OFFSET(Attendance!$A$1,12,7+(7-1)*4)),"")) | AP43: =IF($AF43="","",IFERROR(AVERAGE(OFFSET(Attendance!$A$1,12,5+(8-1)*4),OFFSET(Attendance!$A$1,12,7+(8-1)*4)),"")) | AQ43: =IF($AF43="","",IFERROR(AVERAGE(OFFSET(Attendance!$A$1,12,5+(9-1)*4),OFFSET(Attendance!$A$1,12,7+(9-1)*4)),"")) | AR43: =IF($AF43="","",IFERROR(AVERAGE(OFFSET(Attendance!$A$1,12,5+(10-1)*4),OFFSET(Attendance!$A$1,12,7+(10-1)*4)),"")) | AS43: =IF($AF43="","",IFERROR(AVERAGE(OFFSET(Attendance!$A$1,12,5+(11-1)*4),OFFSET(Attendance!$A$1,12,7+(11-1)*4)),"")) | AT43: =IF($AF43="","",IFERROR(AVERAGE(OFFSET(Attendance!$A$1,12,5+(12-1)*4),OFFSET(Attendance!$A$1,12,7+(12-1)*4)),"")) | AU43: =IF($AF43="","",IFERROR(AVERAGE(OFFSET(Attendance!$A$1,12,5+(13-1)*4),OFFSET(Attendance!$A$1,12,7+(13-1)*4)),"")) | AV43: =IF($AF43="","",IFERROR(AVERAGE(OFFSET(Attendance!$A$1,12,5+(14-1)*4),OFFSET(Attendance!$A$1,12,7+(14-1)*4)),"")) | AW43: =IF($AF43="","",IFERROR(AVERAGE(OFFSET(Attendance!$A$1,12,5+(15-1)*4),OFFSET(Attendance!$A$1,12,7+(15-1)*4)),"")) | AX43: =IF($AF43="","",IFERROR(AVERAGE(OFFSET(Attendance!$A$1,12,5+(16-1)*4),OFFSET(Attendance!$A$1,12,7+(16-1)*4)),"")) | AY43: =IF($AF43="","",IFERROR(AVERAGE(OFFSET(Attendance!$A$1,12,5+(17-1)*4),OFFSET(Attendance!$A$1,12,7+(17-1)*4)),"")) | AZ43: =IF($AF43="","",IFERROR(AVERAGE(OFFSET(Attendance!$A$1,12,5+(18-1)*4),OFFSET(Attendance!$A$1,12,7+(18-1)*4)),"")) | BA43: =IF($AF43="","",IFERROR(AVERAGE(OFFSET(Attendance!$A$1,12,5+(19-1)*4),OFFSET(Attendance!$A$1,12,7+(19-1)*4)),"")) | BB43: =IF($AF43="","",IFERROR(AVERAGE(OFFSET(Attendance!$A$1,12,5+(20-1)*4),OFFSET(Attendance!$A$1,12,7+(20-1)*4)),"")) | BC43: =IF($AF43="","",IFERROR(AVERAGE(OFFSET(Attendance!$A$1,12,5+(21-1)*4),OFFSET(Attendance!$A$1,12,7+(21-1)*4)),"")) | BD43: =IF($AF43="","",IFERROR(AVERAGE(OFFSET(Attendance!$A$1,12,5+(22-1)*4),OFFSET(Attendance!$A$1,12,7+(22-1)*4)),"")) | BE43: =IF($AF43="","",IFERROR(Workings!$D14,"")) | BF43: =IF($AF43="","",IFERROR(Workings!$E14,"")) | BG43: =IF($AF43="","",IFERROR(Workings!$G14,"")) | BH43: =IF($AF43="","",IFERROR(Workings!$H14,"")) -> 0
AF44: =IF(Attendance!$D14="","",Attendance!$D14) -> Semilore Adesanya | AG44: {=IF($AF44="","",_xlfn.TEXTJOIN("",TRUE,IF(Attendance!$E$4:$CN$4="WR",IFERROR(CHOOSE(Attendance!$E14:$CN14,"▁","▃","▅","▆","█"),"·"),"")))} -> ············································ | AH44: {=IF($AF44="","",_xlfn.TEXTJOIN("",TRUE,IF(Attendance!$CP$4:$FY$4="Rating",IFERROR(CHOOSE(ROUNDUP(Attendance!$CP14:$FY14/2,0),"▁","▃","▅","▆","█"),"·"),"")))} -> ······················ | AI44: =IF($AF44="","",IFERROR(AVERAGE(OFFSET(Attendance!$A$1,13,5+(1-1)*4),OFFSET(Attendance!$A$1,13,7+(1-1)*4)),"")) | AJ44: =IF($AF44="","",IFERROR(AVERAGE(OFFSET(Attendance!$A$1,13,5+(2-1)*4),OFFSET(Attendance!$A$1,13,7+(2-1)*4)),"")) | AK44: =IF($AF44="","",IFERROR(AVERAGE(OFFSET(Attendance!$A$1,13,5+(3-1)*4),OFFSET(Attendance!$A$1,13,7+(3-1)*4)),"")) | AL44: =IF($AF44="","",IFERROR(AVERAGE(OFFSET(Attendance!$A$1,13,5+(4-1)*4),OFFSET(Attendance!$A$1,13,7+(4-1)*4)),"")) | AM44: =IF($AF44="","",IFERROR(AVERAGE(OFFSET(Attendance!$A$1,13,5+(5-1)*4),OFFSET(Attendance!$A$1,13,7+(5-1)*4)),"")) | AN44: =IF($AF44="","",IFERROR(AVERAGE(OFFSET(Attendance!$A$1,13,5+(6-1)*4),OFFSET(Attendance!$A$1,13,7+(6-1)*4)),"")) | AO44: =IF($AF44="","",IFERROR(AVERAGE(OFFSET(Attendance!$A$1,13,5+(7-1)*4),OFFSET(Attendance!$A$1,13,7+(7-1)*4)),"")) | AP44: =IF($AF44="","",IFERROR(AVERAGE(OFFSET(Attendance!$A$1,13,5+(8-1)*4),OFFSET(Attendance!$A$1,13,7+(8-1)*4)),"")) | AQ44: =IF($AF44="","",IFERROR(AVERAGE(OFFSET(Attendance!$A$1,13,5+(9-1)*4),OFFSET(Attendance!$A$1,13,7+(9-1)*4)),"")) | AR44: =IF($AF44="","",IFERROR(AVERAGE(OFFSET(Attendance!$A$1,13,5+(10-1)*4),OFFSET(Attendance!$A$1,13,7+(10-1)*4)),"")) | AS44: =IF($AF44="","",IFERROR(AVERAGE(OFFSET(Attendance!$A$1,13,5+(11-1)*4),OFFSET(Attendance!$A$1,13,7+(11-1)*4)),"")) | AT44: =IF($AF44="","",IFERROR(AVERAGE(OFFSET(Attendance!$A$1,13,5+(12-1)*4),OFFSET(Attendance!$A$1,13,7+(12-1)*4)),"")) | AU44: =IF($AF44="","",IFERROR(AVERAGE(OFFSET(Attendance!$A$1,13,5+(13-1)*4),OFFSET(Attendance!$A$1,13,7+(13-1)*4)),"")) | AV44: =IF($AF44="","",IFERROR(AVERAGE(OFFSET(Attendance!$A$1,13,5+(14-1)*4),OFFSET(Attendance!$A$1,13,7+(14-1)*4)),"")) | AW44: =IF($AF44="","",IFERROR(AVERAGE(OFFSET(Attendance!$A$1,13,5+(15-1)*4),OFFSET(Attendance!$A$1,13,7+(15-1)*4)),"")) | AX44: =IF($AF44="","",IFERROR(AVERAGE(OFFSET(Attendance!$A$1,13,5+(16-1)*4),OFFSET(Attendance!$A$1,13,7+(16-1)*4)),"")) | AY44: =IF($AF44="","",IFERROR(AVERAGE(OFFSET(Attendance!$A$1,13,5+(17-1)*4),OFFSET(Attendance!$A$1,13,7+(17-1)*4)),"")) | AZ44: =IF($AF44="","",IFERROR(AVERAGE(OFFSET(Attendance!$A$1,13,5+(18-1)*4),OFFSET(Attendance!$A$1,13,7+(18-1)*4)),"")) | BA44: =IF($AF44="","",IFERROR(AVERAGE(OFFSET(Attendance!$A$1,13,5+(19-1)*4),OFFSET(Attendance!$A$1,13,7+(19-1)*4)),"")) | BB44: =IF($AF44="","",IFERROR(AVERAGE(OFFSET(Attendance!$A$1,13,5+(20-1)*4),OFFSET(Attendance!$A$1,13,7+(20-1)*4)),"")) | BC44: =IF($AF44="","",IFERROR(AVERAGE(OFFSET(Attendance!$A$1,13,5+(21-1)*4),OFFSET(Attendance!$A$1,13,7+(21-1)*4)),"")) | BD44: =IF($AF44="","",IFERROR(AVERAGE(OFFSET(Attendance!$A$1,13,5+(22-1)*4),OFFSET(Attendance!$A$1,13,7+(22-1)*4)),"")) | BE44: =IF($AF44="","",IFERROR(Workings!$D15,"")) | BF44: =IF($AF44="","",IFERROR(Workings!$E15,"")) | BG44: =IF($AF44="","",IFERROR(Workings!$G15,"")) | BH44: =IF($AF44="","",IFERROR(Workings!$H15,"")) -> 0
AF45: =IF(Attendance!$D15="","",Attendance!$D15) -> Hannah Fleming | AG45: {=IF($AF45="","",_xlfn.TEXTJOIN("",TRUE,IF(Attendance!$E$4:$CN$4="WR",IFERROR(CHOOSE(Attendance!$E15:$CN15,"▁","▃","▅","▆","█"),"·"),"")))} -> ············································ | AH45: {=IF($AF45="","",_xlfn.TEXTJOIN("",TRUE,IF(Attendance!$CP$4:$FY$4="Rating",IFERROR(CHOOSE(ROUNDUP(Attendance!$CP15:$FY15/2,0),"▁","▃","▅","▆","█"),"·"),"")))} -> ······················ | AI45: =IF($AF45="","",IFERROR(AVERAGE(OFFSET(Attendance!$A$1,14,5+(1-1)*4),OFFSET(Attendance!$A$1,14,7+(1-1)*4)),"")) | AJ45: =IF($AF45="","",IFERROR(AVERAGE(OFFSET(Attendance!$A$1,14,5+(2-1)*4),OFFSET(Attendance!$A$1,14,7+(2-1)*4)),"")) | AK45: =IF($AF45="","",IFERROR(AVERAGE(OFFSET(Attendance!$A$1,14,5+(3-1)*4),OFFSET(Attendance!$A$1,14,7+(3-1)*4)),"")) | AL45: =IF($AF45="","",IFERROR(AVERAGE(OFFSET(Attendance!$A$1,14,5+(4-1)*4),OFFSET(Attendance!$A$1,14,7+(4-1)*4)),"")) | AM45: =IF($AF45="","",IFERROR(AVERAGE(OFFSET(Attendance!$A$1,14,5+(5-1)*4),OFFSET(Attendance!$A$1,14,7+(5-1)*4)),"")) | AN45: =IF($AF45="","",IFERROR(AVERAGE(OFFSET(Attendance!$A$1,14,5+(6-1)*4),OFFSET(Attendance!$A$1,14,7+(6-1)*4)),"")) | AO45: =IF($AF45="","",IFERROR(AVERAGE(OFFSET(Attendance!$A$1,14,5+(7-1)*4),OFFSET(Attendance!$A$1,14,7+(7-1)*4)),"")) | AP45: =IF($AF45="","",IFERROR(AVERAGE(OFFSET(Attendance!$A$1,14,5+(8-1)*4),OFFSET(Attendance!$A$1,14,7+(8-1)*4)),"")) | AQ45: =IF($AF45="","",IFERROR(AVERAGE(OFFSET(Attendance!$A$1,14,5+(9-1)*4),OFFSET(Attendance!$A$1,14,7+(9-1)*4)),"")) | AR45: =IF($AF45="","",IFERROR(AVERAGE(OFFSET(Attendance!$A$1,14,5+(10-1)*4),OFFSET(Attendance!$A$1,14,7+(10-1)*4)),"")) | AS45: =IF($AF45="","",IFERROR(AVERAGE(OFFSET(Attendance!$A$1,14,5+(11-1)*4),OFFSET(Attendance!$A$1,14,7+(11-1)*4)),"")) | AT45: =IF($AF45="","",IFERROR(AVERAGE(OFFSET(Attendance!$A$1,14,5+(12-1)*4),OFFSET(Attendance!$A$1,14,7+(12-1)*4)),"")) | AU45: =IF($AF45="","",IFERROR(AVERAGE(OFFSET(Attendance!$A$1,14,5+(13-1)*4),OFFSET(Attendance!$A$1,14,7+(13-1)*4)),"")) | AV45: =IF($AF45="","",IFERROR(AVERAGE(OFFSET(Attendance!$A$1,14,5+(14-1)*4),OFFSET(Attendance!$A$1,14,7+(14-1)*4)),"")) | AW45: =IF($AF45="","",IFERROR(AVERAGE(OFFSET(Attendance!$A$1,14,5+(15-1)*4),OFFSET(Attendance!$A$1,14,7+(15-1)*4)),"")) | AX45: =IF($AF45="","",IFERROR(AVERAGE(OFFSET(Attendance!$A$1,14,5+(16-1)*4),OFFSET(Attendance!$A$1,14,7+(16-1)*4)),"")) | AY45: =IF($AF45="","",IFERROR(AVERAGE(OFFSET(Attendance!$A$1,14,5+(17-1)*4),OFFSET(Attendance!$A$1,14,7+(17-1)*4)),"")) | AZ45: =IF($AF45="","",IFERROR(AVERAGE(OFFSET(Attendance!$A$1,14,5+(18-1)*4),OFFSET(Attendance!$A$1,14,7+(18-1)*4)),"")) | BA45: =IF($AF45="","",IFERROR(AVERAGE(OFFSET(Attendance!$A$1,14,5+(19-1)*4),OFFSET(Attendance!$A$1,14,7+(19-1)*4)),"")) | BB45: =IF($AF45="","",IFERROR(AVERAGE(OFFSET(Attendance!$A$1,14,5+(20-1)*4),OFFSET(Attendance!$A$1,14,7+(20-1)*4)),"")) | BC45: =IF($AF45="","",IFERROR(AVERAGE(OFFSET(Attendance!$A$1,14,5+(21-1)*4),OFFSET(Attendance!$A$1,14,7+(21-1)*4)),"")) | BD45: =IF($AF45="","",IFERROR(AVERAGE(OFFSET(Attendance!$A$1,14,5+(22-1)*4),OFFSET(Attendance!$A$1,14,7+(22-1)*4)),"")) | BE45: =IF($AF45="","",IFERROR(Workings!$D16,"")) | BF45: =IF($AF45="","",IFERROR(Workings!$E16,"")) | BG45: =IF($AF45="","",IFERROR(Workings!$G16,"")) | BH45: =IF($AF45="","",IFERROR(Workings!$H16,"")) -> 0
AF46: =IF(Attendance!$D16="","",Attendance!$D16) -> Emma Kelly | AG46: {=IF($AF46="","",_xlfn.TEXTJOIN("",TRUE,IF(Attendance!$E$4:$CN$4="WR",IFERROR(CHOOSE(Attendance!$E16:$CN16,"▁","▃","▅","▆","█"),"·"),"")))} -> ············································ | AH46: {=IF($AF46="","",_xlfn.TEXTJOIN("",TRUE,IF(Attendance!$CP$4:$FY$4="Rating",IFERROR(CHOOSE(ROUNDUP(Attendance!$CP16:$FY16/2,0),"▁","▃","▅","▆","█"),"·"),"")))} -> ······················ | AI46: =IF($AF46="","",IFERROR(AVERAGE(OFFSET(Attendance!$A$1,15,5+(1-1)*4),OFFSET(Attendance!$A$1,15,7+(1-1)*4)),"")) | AJ46: =IF($AF46="","",IFERROR(AVERAGE(OFFSET(Attendance!$A$1,15,5+(2-1)*4),OFFSET(Attendance!$A$1,15,7+(2-1)*4)),"")) | AK46: =IF($AF46="","",IFERROR(AVERAGE(OFFSET(Attendance!$A$1,15,5+(3-1)*4),OFFSET(Attendance!$A$1,15,7+(3-1)*4)),"")) | AL46: =IF($AF46="","",IFERROR(AVERAGE(OFFSET(Attendance!$A$1,15,5+(4-1)*4),OFFSET(Attendance!$A$1,15,7+(4-1)*4)),"")) | AM46: =IF($AF46="","",IFERROR(AVERAGE(OFFSET(Attendance!$A$1,15,5+(5-1)*4),OFFSET(Attendance!$A$1,15,7+(5-1)*4)),"")) | AN46: =IF($AF46="","",IFERROR(AVERAGE(OFFSET(Attendance!$A$1,15,5+(6-1)*4),OFFSET(Attendance!$A$1,15,7+(6-1)*4)),"")) | AO46: =IF($AF46="","",IFERROR(AVERAGE(OFFSET(Attendance!$A$1,15,5+(7-1)*4),OFFSET(Attendance!$A$1,15,7+(7-1)*4)),"")) | AP46: =IF($AF46="","",IFERROR(AVERAGE(OFFSET(Attendance!$A$1,15,5+(8-1)*4),OFFSET(Attendance!$A$1,15,7+(8-1)*4)),"")) | AQ46: =IF($AF46="","",IFERROR(AVERAGE(OFFSET(Attendance!$A$1,15,5+(9-1)*4),OFFSET(Attendance!$A$1,15,7+(9-1)*4)),"")) | AR46: =IF($AF46="","",IFERROR(AVERAGE(OFFSET(Attendance!$A$1,15,5+(10-1)*4),OFFSET(Attendance!$A$1,15,7+(10-1)*4)),"")) | AS46: =IF($AF46="","",IFERROR(AVERAGE(OFFSET(Attendance!$A$1,15,5+(11-1)*4),OFFSET(Attendance!$A$1,15,7+(11-1)*4)),"")) | AT46: =IF($AF46="","",IFERROR(AVERAGE(OFFSET(Attendance!$A$1,15,5+(12-1)*4),OFFSET(Attendance!$A$1,15,7+(12-1)*4)),"")) | AU46: =IF($AF46="","",IFERROR(AVERAGE(OFFSET(Attendance!$A$1,15,5+(13-1)*4),OFFSET(Attendance!$A$1,15,7+(13-1)*4)),"")) | AV46: =IF($AF46="","",IFERROR(AVERAGE(OFFSET(Attendance!$A$1,15,5+(14-1)*4),OFFSET(Attendance!$A$1,15,7+(14-1)*4)),"")) | AW46: =IF($AF46="","",IFERROR(AVERAGE(OFFSET(Attendance!$A$1,15,5+(15-1)*4),OFFSET(Attendance!$A$1,15,7+(15-1)*4)),"")) | AX46: =IF($AF46="","",IFERROR(AVERAGE(OFFSET(Attendance!$A$1,15,5+(16-1)*4),OFFSET(Attendance!$A$1,15,7+(16-1)*4)),"")) | AY46: =IF($AF46="","",IFERROR(AVERAGE(OFFSET(Attendance!$A$1,15,5+(17-1)*4),OFFSET(Attendance!$A$1,15,7+(17-1)*4)),"")) | AZ46: =IF($AF46="","",IFERROR(AVERAGE(OFFSET(Attendance!$A$1,15,5+(18-1)*4),OFFSET(Attendance!$A$1,15,7+(18-1)*4)),"")) | BA46: =IF($AF46="","",IFERROR(AVERAGE(OFFSET(Attendance!$A$1,15,5+(19-1)*4),OFFSET(Attendance!$A$1,15,7+(19-1)*4)),"")) | BB46: =IF($AF46="","",IFERROR(AVERAGE(OFFSET(Attendance!$A$1,15,5+(20-1)*4),OFFSET(Attendance!$A$1,15,7+(20-1)*4)),"")) | BC46: =IF($AF46="","",IFERROR(AVERAGE(OFFSET(Attendance!$A$1,15,5+(21-1)*4),OFFSET(Attendance!$A$1,15,7+(21-1)*4)),"")) | BD46: =IF($AF46="","",IFERROR(AVERAGE(OFFSET(Attendance!$A$1,15,5+(22-1)*4),OFFSET(Attendance!$A$1,15,7+(22-1)*4)),"")) | BE46: =IF($AF46="","",IFERROR(Workings!$D17,"")) | BF46: =IF($AF46="","",IFERROR(Workings!$E17,"")) | BG46: =IF($AF46="","",IFERROR(Workings!$G17,"")) | BH46: =IF($AF46="","",IFERROR(Workings!$H17,"")) -> 0
AF47: =IF(Attendance!$D17="","",Attendance!$D17) -> Roma Memon | AG47: {=IF($AF47="","",_xlfn.TEXTJOIN("",TRUE,IF(Attendance!$E$4:$CN$4="WR",IFERROR(CHOOSE(Attendance!$E17:$CN17,"▁","▃","▅","▆","█"),"·"),"")))} -> ············································ | AH47: {=IF($AF47="","",_xlfn.TEXTJOIN("",TRUE,IF(Attendance!$CP$4:$FY$4="Rating",IFERROR(CHOOSE(ROUNDUP(Attendance!$CP17:$FY17/2,0),"▁","▃","▅","▆","█"),"·"),"")))} -> ······················ | AI47: =IF($AF47="","",IFERROR(AVERAGE(OFFSET(Attendance!$A$1,16,5+(1-1)*4),OFFSET(Attendance!$A$1,16,7+(1-1)*4)),"")) | AJ47: =IF($AF47="","",IFERROR(AVERAGE(OFFSET(Attendance!$A$1,16,5+(2-1)*4),OFFSET(Attendance!$A$1,16,7+(2-1)*4)),"")) | AK47: =IF($AF47="","",IFERROR(AVERAGE(OFFSET(Attendance!$A$1,16,5+(3-1)*4),OFFSET(Attendance!$A$1,16,7+(3-1)*4)),"")) | AL47: =IF($AF47="","",IFERROR(AVERAGE(OFFSET(Attendance!$A$1,16,5+(4-1)*4),OFFSET(Attendance!$A$1,16,7+(4-1)*4)),"")) | AM47: =IF($AF47="","",IFERROR(AVERAGE(OFFSET(Attendance!$A$1,16,5+(5-1)*4),OFFSET(Attendance!$A$1,16,7+(5-1)*4)),"")) | AN47: =IF($AF47="","",IFERROR(AVERAGE(OFFSET(Attendance!$A$1,16,5+(6-1)*4),OFFSET(Attendance!$A$1,16,7+(6-1)*4)),"")) | AO47: =IF($AF47="","",IFERROR(AVERAGE(OFFSET(Attendance!$A$1,16,5+(7-1)*4),OFFSET(Attendance!$A$1,16,7+(7-1)*4)),"")) | AP47: =IF($AF47="","",IFERROR(AVERAGE(OFFSET(Attendance!$A$1,16,5+(8-1)*4),OFFSET(Attendance!$A$1,16,7+(8-1)*4)),"")) | AQ47: =IF($AF47="","",IFERROR(AVERAGE(OFFSET(Attendance!$A$1,16,5+(9-1)*4),OFFSET(Attendance!$A$1,16,7+(9-1)*4)),"")) | AR47: =IF($AF47="","",IFERROR(AVERAGE(OFFSET(Attendance!$A$1,16,5+(10-1)*4),OFFSET(Attendance!$A$1,16,7+(10-1)*4)),"")) | AS47: =IF($AF47="","",IFERROR(AVERAGE(OFFSET(Attendance!$A$1,16,5+(11-1)*4),OFFSET(Attendance!$A$1,16,7+(11-1)*4)),"")) | AT47: =IF($AF47="","",IFERROR(AVERAGE(OFFSET(Attendance!$A$1,16,5+(12-1)*4),OFFSET(Attendance!$A$1,16,7+(12-1)*4)),"")) | AU47: =IF($AF47="","",IFERROR(AVERAGE(OFFSET(Attendance!$A$1,16,5+(13-1)*4),OFFSET(Attendance!$A$1,16,7+(13-1)*4)),"")) | AV47: =IF($AF47="","",IFERROR(AVERAGE(OFFSET(Attendance!$A$1,16,5+(14-1)*4),OFFSET(Attendance!$A$1,16,7+(14-1)*4)),"")) | AW47: =IF($AF47="","",IFERROR(AVERAGE(OFFSET(Attendance!$A$1,16,5+(15-1)*4),OFFSET(Attendance!$A$1,16,7+(15-1)*4)),"")) | AX47: =IF($AF47="","",IFERROR(AVERAGE(OFFSET(Attendance!$A$1,16,5+(16-1)*4),OFFSET(Attendance!$A$1,16,7+(16-1)*4)),"")) | AY47: =IF($AF47="","",IFERROR(AVERAGE(OFFSET(Attendance!$A$1,16,5+(17-1)*4),OFFSET(Attendance!$A$1,16,7+(17-1)*4)),"")) | AZ47: =IF($AF47="","",IFERROR(AVERAGE(OFFSET(Attendance!$A$1,16,5+(18-1)*4),OFFSET(Attendance!$A$1,16,7+(18-1)*4)),"")) | BA47: =IF($AF47="","",IFERROR(AVERAGE(OFFSET(Attendance!$A$1,16,5+(19-1)*4),OFFSET(Attendance!$A$1,16,7+(19-1)*4)),"")) | BB47: =IF($AF47="","",IFERROR(AVERAGE(OFFSET(Attendance!$A$1,16,5+(20-1)*4),OFFSET(Attendance!$A$1,16,7+(20-1)*4)),"")) | BC47: =IF($AF47="","",IFERROR(AVERAGE(OFFSET(Attendance!$A$1,16,5+(21-1)*4),OFFSET(Attendance!$A$1,16,7+(21-1)*4)),"")) | BD47: =IF($AF47="","",IFERROR(AVERAGE(OFFSET(Attendance!$A$1,16,5+(22-1)*4),OFFSET(Attendance!$A$1,16,7+(22-1)*4)),"")) | BE47: =IF($AF47="","",IFERROR(Workings!$D18,"")) | BF47: =IF($AF47="","",IFERROR(Workings!$E18,"")) | BG47: =IF($AF47="","",IFERROR(Workings!$G18,"")) | BH47: =IF($AF47="","",IFERROR(Workings!$H18,"")) -> 0
AF48: =IF(Attendance!$D18="","",Attendance!$D18) -> Emma Dromgoole | AG48: {=IF($AF48="","",_xlfn.TEXTJOIN("",TRUE,IF(Attendance!$E$4:$CN$4="WR",IFERROR(CHOOSE(Attendance!$E18:$CN18,"▁","▃","▅","▆","█"),"·"),"")))} -> ············································ | AH48: {=IF($AF48="","",_xlfn.TEXTJOIN("",TRUE,IF(Attendance!$CP$4:$FY$4="Rating",IFERROR(CHOOSE(ROUNDUP(Attendance!$CP18:$FY18/2,0),"▁","▃","▅","▆","█"),"·"),"")))} -> ······················ | AI48: =IF($AF48="","",IFERROR(AVERAGE(OFFSET(Attendance!$A$1,17,5+(1-1)*4),OFFSET(Attendance!$A$1,17,7+(1-1)*4)),"")) | AJ48: =IF($AF48="","",IFERROR(AVERAGE(OFFSET(Attendance!$A$1,17,5+(2-1)*4),OFFSET(Attendance!$A$1,17,7+(2-1)*4)),"")) | AK48: =IF($AF48="","",IFERROR(AVERAGE(OFFSET(Attendance!$A$1,17,5+(3-1)*4),OFFSET(Attendance!$A$1,17,7+(3-1)*4)),"")) | AL48: =IF($AF48="","",IFERROR(AVERAGE(OFFSET(Attendance!$A$1,17,5+(4-1)*4),OFFSET(Attendance!$A$1,17,7+(4-1)*4)),"")) | AM48: =IF($AF48="","",IFERROR(AVERAGE(OFFSET(Attendance!$A$1,17,5+(5-1)*4),OFFSET(Attendance!$A$1,17,7+(5-1)*4)),"")) | AN48: =IF($AF48="","",IFERROR(AVERAGE(OFFSET(Attendance!$A$1,17,5+(6-1)*4),OFFSET(Attendance!$A$1,17,7+(6-1)*4)),"")) | AO48: =IF($AF48="","",IFERROR(AVERAGE(OFFSET(Attendance!$A$1,17,5+(7-1)*4),OFFSET(Attendance!$A$1,17,7+(7-1)*4)),"")) | AP48: =IF($AF48="","",IFERROR(AVERAGE(OFFSET(Attendance!$A$1,17,5+(8-1)*4),OFFSET(Attendance!$A$1,17,7+(8-1)*4)),"")) | AQ48: =IF($AF48="","",IFERROR(AVERAGE(OFFSET(Attendance!$A$1,17,5+(9-1)*4),OFFSET(Attendance!$A$1,17,7+(9-1)*4)),"")) | AR48: =IF($AF48="","",IFERROR(AVERAGE(OFFSET(Attendance!$A$1,17,5+(10-1)*4),OFFSET(Attendance!$A$1,17,7+(10-1)*4)),"")) | AS48: =IF($AF48="","",IFERROR(AVERAGE(OFFSET(Attendance!$A$1,17,5+(11-1)*4),OFFSET(Attendance!$A$1,17,7+(11-1)*4)),"")) | AT48: =IF($AF48="","",IFERROR(AVERAGE(OFFSET(Attendance!$A$1,17,5+(12-1)*4),OFFSET(Attendance!$A$1,17,7+(12-1)*4)),"")) | AU48: =IF($AF48="","",IFERROR(AVERAGE(OFFSET(Attendance!$A$1,17,5+(13-1)*4),OFFSET(Attendance!$A$1,17,7+(13-1)*4)),"")) | AV48: =IF($AF48="","",IFERROR(AVERAGE(OFFSET(Attendance!$A$1,17,5+(14-1)*4),OFFSET(Attendance!$A$1,17,7+(14-1)*4)),"")) | AW48: =IF($AF48="","",IFERROR(AVERAGE(OFFSET(Attendance!$A$1,17,5+(15-1)*4),OFFSET(Attendance!$A$1,17,7+(15-1)*4)),"")) | AX48: =IF($AF48="","",IFERROR(AVERAGE(OFFSET(Attendance!$A$1,17,5+(16-1)*4),OFFSET(Attendance!$A$1,17,7+(16-1)*4)),"")) | AY48: =IF($AF48="","",IFERROR(AVERAGE(OFFSET(Attendance!$A$1,17,5+(17-1)*4),OFFSET(Attendance!$A$1,17,7+(17-1)*4)),"")) | AZ48: =IF($AF48="","",IFERROR(AVERAGE(OFFSET(Attendance!$A$1,17,5+(18-1)*4),OFFSET(Attendance!$A$1,17,7+(18-1)*4)),"")) | BA48: =IF($AF48="","",IFERROR(AVERAGE(OFFSET(Attendance!$A$1,17,5+(19-1)*4),OFFSET(Attendance!$A$1,17,7+(19-1)*4)),"")) | BB48: =IF($AF48="","",IFERROR(AVERAGE(OFFSET(Attendance!$A$1,17,5+(20-1)*4),OFFSET(Attendance!$A$1,17,7+(20-1)*4)),"")) | BC48: =IF($AF48="","",IFERROR(AVERAGE(OFFSET(Attendance!$A$1,17,5+(21-1)*4),OFFSET(Attendance!$A$1,17,7+(21-1)*4)),"")) | BD48: =IF($AF48="","",IFERROR(AVERAGE(OFFSET(Attendance!$A$1,17,5+(22-1)*4),OFFSET(Attendance!$A$1,17,7+(22-1)*4)),"")) | BE48: =IF($AF48="","",IFERROR(Workings!$D19,"")) | BF48: =IF($AF48="","",IFERROR(Workings!$E19,"")) | BG48: =IF($AF48="","",IFERROR(Workings!$G19,"")) | BH48: =IF($AF48="","",IFERROR(Workings!$H19,"")) -> 0
AF49: =IF(Attendance!$D19="","",Attendance!$D19) -> Elsie Morrison | AG49: {=IF($AF49="","",_xlfn.TEXTJOIN("",TRUE,IF(Attendance!$E$4:$CN$4="WR",IFERROR(CHOOSE(Attendance!$E19:$CN19,"▁","▃","▅","▆","█"),"·"),"")))} -> ············································ | AH49: {=IF($AF49="","",_xlfn.TEXTJOIN("",TRUE,IF(Attendance!$CP$4:$FY$4="Rating",IFERROR(CHOOSE(ROUNDUP(Attendance!$CP19:$FY19/2,0),"▁","▃","▅","▆","█"),"·"),"")))} -> ······················ | AI49: =IF($AF49="","",IFERROR(AVERAGE(OFFSET(Attendance!$A$1,18,5+(1-1)*4),OFFSET(Attendance!$A$1,18,7+(1-1)*4)),"")) | AJ49: =IF($AF49="","",IFERROR(AVERAGE(OFFSET(Attendance!$A$1,18,5+(2-1)*4),OFFSET(Attendance!$A$1,18,7+(2-1)*4)),"")) | AK49: =IF($AF49="","",IFERROR(AVERAGE(OFFSET(Attendance!$A$1,18,5+(3-1)*4),OFFSET(Attendance!$A$1,18,7+(3-1)*4)),"")) | AL49: =IF($AF49="","",IFERROR(AVERAGE(OFFSET(Attendance!$A$1,18,5+(4-1)*4),OFFSET(Attendance!$A$1,18,7+(4-1)*4)),"")) | AM49: =IF($AF49="","",IFERROR(AVERAGE(OFFSET(Attendance!$A$1,18,5+(5-1)*4),OFFSET(Attendance!$A$1,18,7+(5-1)*4)),"")) | AN49: =IF($AF49="","",IFERROR(AVERAGE(OFFSET(Attendance!$A$1,18,5+(6-1)*4),OFFSET(Attendance!$A$1,18,7+(6-1)*4)),"")) | AO49: =IF($AF49="","",IFERROR(AVERAGE(OFFSET(Attendance!$A$1,18,5+(7-1)*4),OFFSET(Attendance!$A$1,18,7+(7-1)*4)),"")) | AP49: =IF($AF49="","",IFERROR(AVERAGE(OFFSET(Attendance!$A$1,18,5+(8-1)*4),OFFSET(Attendance!$A$1,18,7+(8-1)*4)),"")) | AQ49: =IF($AF49="","",IFERROR(AVERAGE(OFFSET(Attendance!$A$1,18,5+(9-1)*4),OFFSET(Attendance!$A$1,18,7+(9-1)*4)),"")) | AR49: =IF($AF49="","",IFERROR(AVERAGE(OFFSET(Attendance!$A$1,18,5+(10-1)*4),OFFSET(Attendance!$A$1,18,7+(10-1)*4)),"")) | AS49: =IF($AF49="","",IFERROR(AVERAGE(OFFSET(Attendance!$A$1,18,5+(11-1)*4),OFFSET(Attendance!$A$1,18,7+(11-1)*4)),"")) | AT49: =IF($AF49="","",IFERROR(AVERAGE(OFFSET(Attendance!$A$1,18,5+(12-1)*4),OFFSET(Attendance!$A$1,18,7+(12-1)*4)),"")) | AU49: =IF($AF49="","",IFERROR(AVERAGE(OFFSET(Attendance!$A$1,18,5+(13-1)*4),OFFSET(Attendance!$A$1,18,7+(13-1)*4)),"")) | AV49: =IF($AF49="","",IFERROR(AVERAGE(OFFSET(Attendance!$A$1,18,5+(14-1)*4),OFFSET(Attendance!$A$1,18,7+(14-1)*4)),"")) | AW49: =IF($AF49="","",IFERROR(AVERAGE(OFFSET(Attendance!$A$1,18,5+(15-1)*4),OFFSET(Attendance!$A$1,18,7+(15-1)*4)),"")) | AX49: =IF($AF49="","",IFERROR(AVERAGE(OFFSET(Attendance!$A$1,18,5+(16-1)*4),OFFSET(Attendance!$A$1,18,7+(16-1)*4)),"")) | AY49: =IF($AF49="","",IFERROR(AVERAGE(OFFSET(Attendance!$A$1,18,5+(17-1)*4),OFFSET(Attendance!$A$1,18,7+(17-1)*4)),"")) | AZ49: =IF($AF49="","",IFERROR(AVERAGE(OFFSET(Attendance!$A$1,18,5+(18-1)*4),OFFSET(Attendance!$A$1,18,7+(18-1)*4)),"")) | BA49: =IF($AF49="","",IFERROR(AVERAGE(OFFSET(Attendance!$A$1,18,5+(19-1)*4),OFFSET(Attendance!$A$1,18,7+(19-1)*4)),"")) | BB49: =IF($AF49="","",IFERROR(AVERAGE(OFFSET(Attendance!$A$1,18,5+(20-1)*4),OFFSET(Attendance!$A$1,18,7+(20-1)*4)),"")) | BC49: =IF($AF49="","",IFERROR(AVERAGE(OFFSET(Attendance!$A$1,18,5+(21-1)*4),OFFSET(Attendance!$A$1,18,7+(21-1)*4)),"")) | BD49: =IF($AF49="","",IFERROR(AVERAGE(OFFSET(Attendance!$A$1,18,5+(22-1)*4),OFFSET(Attendance!$A$1,18,7+(22-1)*4)),"")) | BE49: =IF($AF49="","",IFERROR(Workings!$D20,"")) | BF49: =IF($AF49="","",IFERROR(Workings!$E20,"")) | BG49: =IF($AF49="","",IFERROR(Workings!$G20,"")) | BH49: =IF($AF49="","",IFERROR(Workings!$H20,"")) -> 0
AF50: =IF(Attendance!$D20="","",Attendance!$D20) -> Zara Freeman | AG50: {=IF($AF50="","",_xlfn.TEXTJOIN("",TRUE,IF(Attendance!$E$4:$CN$4="WR",IFERROR(CHOOSE(Attendance!$E20:$CN20,"▁","▃","▅","▆","█"),"·"),"")))} -> ············································ | AH50: {=IF($AF50="","",_xlfn.TEXTJOIN("",TRUE,IF(Attendance!$CP$4:$FY$4="Rating",IFERROR(CHOOSE(ROUNDUP(Attendance!$CP20:$FY20/2,0),"▁","▃","▅","▆","█"),"·"),"")))} -> ······················ | AI50: =IF($AF50="","",IFERROR(AVERAGE(OFFSET(Attendance!$A$1,19,5+(1-1)*4),OFFSET(Attendance!$A$1,19,7+(1-1)*4)),"")) | AJ50: =IF($AF50="","",IFERROR(AVERAGE(OFFSET(Attendance!$A$1,19,5+(2-1)*4),OFFSET(Attendance!$A$1,19,7+(2-1)*4)),"")) | AK50: =IF($AF50="","",IFERROR(AVERAGE(OFFSET(Attendance!$A$1,19,5+(3-1)*4),OFFSET(Attendance!$A$1,19,7+(3-1)*4)),"")) | AL50: =IF($AF50="","",IFERROR(AVERAGE(OFFSET(Attendance!$A$1,19,5+(4-1)*4),OFFSET(Attendance!$A$1,19,7+(4-1)*4)),"")) | AM50: =IF($AF50="","",IFERROR(AVERAGE(OFFSET(Attendance!$A$1,19,5+(5-1)*4),OFFSET(Attendance!$A$1,19,7+(5-1)*4)),"")) | AN50: =IF($AF50="","",IFERROR(AVERAGE(OFFSET(Attendance!$A$1,19,5+(6-1)*4),OFFSET(Attendance!$A$1,19,7+(6-1)*4)),"")) | AO50: =IF($AF50="","",IFERROR(AVERAGE(OFFSET(Attendance!$A$1,19,5+(7-1)*4),OFFSET(Attendance!$A$1,19,7+(7-1)*4)),"")) | AP50: =IF($AF50="","",IFERROR(AVERAGE(OFFSET(Attendance!$A$1,19,5+(8-1)*4),OFFSET(Attendance!$A$1,19,7+(8-1)*4)),"")) | AQ50: =IF($AF50="","",IFERROR(AVERAGE(OFFSET(Attendance!$A$1,19,5+(9-1)*4),OFFSET(Attendance!$A$1,19,7+(9-1)*4)),"")) | AR50: =IF($AF50="","",IFERROR(AVERAGE(OFFSET(Attendance!$A$1,19,5+(10-1)*4),OFFSET(Attendance!$A$1,19,7+(10-1)*4)),"")) | AS50: =IF($AF50="","",IFERROR(AVERAGE(OFFSET(Attendance!$A$1,19,5+(11-1)*4),OFFSET(Attendance!$A$1,19,7+(11-1)*4)),"")) | AT50: =IF($AF50="","",IFERROR(AVERAGE(OFFSET(Attendance!$A$1,19,5+(12-1)*4),OFFSET(Attendance!$A$1,19,7+(12-1)*4)),"")) | AU50: =IF($AF50="","",IFERROR(AVERAGE(OFFSET(Attendance!$A$1,19,5+(13-1)*4),OFFSET(Attendance!$A$1,19,7+(13-1)*4)),"")) | AV50: =IF($AF50="","",IFERROR(AVERAGE(OFFSET(Attendance!$A$1,19,5+(14-1)*4),OFFSET(Attendance!$A$1,19,7+(14-1)*4)),"")) | AW50: =IF($AF50="","",IFERROR(AVERAGE(OFFSET(Attendance!$A$1,19,5+(15-1)*4),OFFSET(Attendance!$A$1,19,7+(15-1)*4)),"")) | AX50: =IF($AF50="","",IFERROR(AVERAGE(OFFSET(Attendance!$A$1,19,5+(16-1)*4),OFFSET(Attendance!$A$1,19,7+(16-1)*4)),"")) | AY50: =IF($AF50="","",IFERROR(AVERAGE(OFFSET(Attendance!$A$1,19,5+(17-1)*4),OFFSET(Attendance!$A$1,19,7+(17-1)*4)),"")) | AZ50: =IF($AF50="","",IFERROR(AVERAGE(OFFSET(Attendance!$A$1,19,5+(18-1)*4),OFFSET(Attendance!$A$1,19,7+(18-1)*4)),"")) | BA50: =IF($AF50="","",IFERROR(AVERAGE(OFFSET(Attendance!$A$1,19,5+(19-1)*4),OFFSET(Attendance!$A$1,19,7+(19-1)*4)),"")) | BB50: =IF($AF50="","",IFERROR(AVERAGE(OFFSET(Attendance!$A$1,19,5+(20-1)*4),OFFSET(Attendance!$A$1,19,7+(20-1)*4)),"")) | BC50: =IF($AF50="","",IFERROR(AVERAGE(OFFSET(Attendance!$A$1,19,5+(21-1)*4),OFFSET(Attendance!$A$1,19,7+(21-1)*4)),"")) | BD50: =IF($AF50="","",IFERROR(AVERAGE(OFFSET(Attendance!$A$1,19,5+(22-1)*4),OFFSET(Attendance!$A$1,19,7+(22-1)*4)),"")) | BE50: =IF($AF50="","",IFERROR(Workings!$D21,"")) | BF50: =IF($AF50="","",IFERROR(Workings!$E21,"")) | BG50: =IF($AF50="","",IFERROR(Workings!$G21,"")) | BH50: =IF($AF50="","",IFERROR(Workings!$H21,"")) -> 0
AF51: =IF(Attendance!$D21="","",Attendance!$D21) -> Marianna | AG51: {=IF($AF51="","",_xlfn.TEXTJOIN("",TRUE,IF(Attendance!$E$4:$CN$4="WR",IFERROR(CHOOSE(Attendance!$E21:$CN21,"▁","▃","▅","▆","█"),"·"),"")))} -> ············································ | AH51: {=IF($AF51="","",_xlfn.TEXTJOIN("",TRUE,IF(Attendance!$CP$4:$FY$4="Rating",IFERROR(CHOOSE(ROUNDUP(Attendance!$CP21:$FY21/2,0),"▁","▃","▅","▆","█"),"·"),"")))} -> ······················ | AI51: =IF($AF51="","",IFERROR(AVERAGE(OFFSET(Attendance!$A$1,20,5+(1-1)*4),OFFSET(Attendance!$A$1,20,7+(1-1)*4)),"")) | AJ51: =IF($AF51="","",IFERROR(AVERAGE(OFFSET(Attendance!$A$1,20,5+(2-1)*4),OFFSET(Attendance!$A$1,20,7+(2-1)*4)),"")) | AK51: =IF($AF51="","",IFERROR(AVERAGE(OFFSET(Attendance!$A$1,20,5+(3-1)*4),OFFSET(Attendance!$A$1,20,7+(3-1)*4)),"")) | AL51: =IF($AF51="","",IFERROR(AVERAGE(OFFSET(Attendance!$A$1,20,5+(4-1)*4),OFFSET(Attendance!$A$1,20,7+(4-1)*4)),"")) | AM51: =IF($AF51="","",IFERROR(AVERAGE(OFFSET(Attendance!$A$1,20,5+(5-1)*4),OFFSET(Attendance!$A$1,20,7+(5-1)*4)),"")) | AN51: =IF($AF51="","",IFERROR(AVERAGE(OFFSET(Attendance!$A$1,20,5+(6-1)*4),OFFSET(Attendance!$A$1,20,7+(6-1)*4)),"")) | AO51: =IF($AF51="","",IFERROR(AVERAGE(OFFSET(Attendance!$A$1,20,5+(7-1)*4),OFFSET(Attendance!$A$1,20,7+(7-1)*4)),"")) | AP51: =IF($AF51="","",IFERROR(AVERAGE(OFFSET(Attendance!$A$1,20,5+(8-1)*4),OFFSET(Attendance!$A$1,20,7+(8-1)*4)),"")) | AQ51: =IF($AF51="","",IFERROR(AVERAGE(OFFSET(Attendance!$A$1,20,5+(9-1)*4),OFFSET(Attendance!$A$1,20,7+(9-1)*4)),"")) | AR51: =IF($AF51="","",IFERROR(AVERAGE(OFFSET(Attendance!$A$1,20,5+(10-1)*4),OFFSET(Attendance!$A$1,20,7+(10-1)*4)),"")) | AS51: =IF($AF51="","",IFERROR(AVERAGE(OFFSET(Attendance!$A$1,20,5+(11-1)*4),OFFSET(Attendance!$A$1,20,7+(11-1)*4)),"")) | AT51: =IF($AF51="","",IFERROR(AVERAGE(OFFSET(Attendance!$A$1,20,5+(12-1)*4),OFFSET(Attendance!$A$1,20,7+(12-1)*4)),"")) | AU51: =IF($AF51="","",IFERROR(AVERAGE(OFFSET(Attendance!$A$1,20,5+(13-1)*4),OFFSET(Attendance!$A$1,20,7+(13-1)*4)),"")) | AV51: =IF($AF51="","",IFERROR(AVERAGE(OFFSET(Attendance!$A$1,20,5+(14-1)*4),OFFSET(Attendance!$A$1,20,7+(14-1)*4)),"")) | AW51: =IF($AF51="","",IFERROR(AVERAGE(OFFSET(Attendance!$A$1,20,5+(15-1)*4),OFFSET(Attendance!$A$1,20,7+(15-1)*4)),"")) | AX51: =IF($AF51="","",IFERROR(AVERAGE(OFFSET(Attendance!$A$1,20,5+(16-1)*4),OFFSET(Attendance!$A$1,20,7+(16-1)*4)),"")) | AY51: =IF($AF51="","",IFERROR(AVERAGE(OFFSET(Attendance!$A$1,20,5+(17-1)*4),OFFSET(Attendance!$A$1,20,7+(17-1)*4)),"")) | AZ51: =IF($AF51="","",IFERROR(AVERAGE(OFFSET(Attendance!$A$1,20,5+(18-1)*4),OFFSET(Attendance!$A$1,20,7+(18-1)*4)),"")) | BA51: =IF($AF51="","",IFERROR(AVERAGE(OFFSET(Attendance!$A$1,20,5+(19-1)*4),OFFSET(Attendance!$A$1,20,7+(19-1)*4)),"")) | BB51: =IF($AF51="","",IFERROR(AVERAGE(OFFSET(Attendance!$A$1,20,5+(20-1)*4),OFFSET(Attendance!$A$1,20,7+(20-1)*4)),"")) | BC51: =IF($AF51="","",IFERROR(AVERAGE(OFFSET(Attendance!$A$1,20,5+(21-1)*4),OFFSET(Attendance!$A$1,20,7+(21-1)*4)),"")) | BD51: =IF($AF51="","",IFERROR(AVERAGE(OFFSET(Attendance!$A$1,20,5+(22-1)*4),OFFSET(Attendance!$A$1,20,7+(22-1)*4)),"")) | BE51: =IF($AF51="","",IFERROR(Workings!$D22,"")) | BF51: =IF($AF51="","",IFERROR(Workings!$E22,"")) | BG51: =IF($AF51="","",IFERROR(Workings!$G22,"")) | BH51: =IF($AF51="","",IFERROR(Workings!$H22,"")) -> 0
